Workbook

Sheet Tanah
A2: VALIDASI INVENTARIS BARANG TANAH
A3: DATA HASIL INVENTARISASI INSPEKTORAT S/D 2018
B4: Provinsi | C4: : | D4: Jawa Tngah
B5: Kab./Kota | C5: : | D5: Boyolali
B6: Kecamatan | C6: : | D6: Klego
B7: Desa | C7: : | D7: Klego
A9: No. | B9: Uraian | C9: N o m o r | F9: Luas (M2) | G9: Tahun Pengadaan | H9: Letak/ Alamat | I9: Status Tanah | L9: Penggunaan | M9: Asal usul | N9: Harga (ribuan Rp) | O9: Keterangan | P9: DI ISI SESUAI RINCIAN SISKEUDES
C10: Kode Barang | E10: Register | I10: Hak | J10: Sertifikat
J11: Tanggal | K11: Nomor
A12: 1 | B12: 2 | C12: 3 | E12: 4 | F12: 5 | G12: 6 | H12: 7 | I12: 8 | J12: 9 | K12: 10 | L12: 11 | M12: 12 | N12: 13 | O12: 14
A13: 1 | B13: TANAH KAS DESA | F13: 11030 | G13: 1960 | H13: Ngembat RT 14 | I13: PAKAI | J13: 25-05-2019 | K13: 00033 | L13: PERTANIAN | M13: C. 317 Ps 131 Sl. I | N13: =F13*103000 -> 1136090000 | O13: Ex Bengkok Kadus III | P13: Tanah Pertanian
A14: =A13+1 -> 2 | B14: TANAH KAS DESA | F14: 5290 | G14: 1960 | H14: Karanganyar | I14: PAKAI | J14: 25-05-2019 | K14: 00029 | L14: PERTANIAN | M14: C. 316 Ps 459 SL. I Seb | N14: =F14*48000 -> 253920000 | O14: Ex Bengkok Sekdes | P14: Tanah Pertanian
A15: =A14+1 -> 3 | B15: TANAH KAS DESA | F15: 5515 | G15: 1960 | H15: Karanganyar | I15: PAKAI | L15: Kantor | M15: C. 802 Ps 100-101 SV | N15: =F15*102000 -> 562530000 | O15: Kantor Desa | P15: Tanah Untuk Bangunan Gedung
A16: =A15+1 -> 4 | B16: TANAH KAS DESA | F16: 8880 | G16: 1960 | H16: Klalingan | I16: PAKAI | J16: 31-07-2019 | K16: 00053 | L16: PERTANIAN | M16: Tanah Milik Adat | N16: =F16*103000 -> 914640000 | O16: Ex Bengkok Kades | P16: Tanah Pertanian
A17: =A16+1 -> 5 | B17: TANAH KAS DESA | F17: 155 | G17: 1960 | H17: Kedokan | I17: PAKAI | J17: 16-07-2019 | K17: 00052 | L17: PERTANIAN | M17: Tanah Milik Adat | N17: =F17*103000 -> 15965000 | O17: OO | P17: Tanah Pertanian
A18: =A17+1 -> 6 | B18: TANAH KAS DESA | F18: 99 | G18: 1960 | H18: Kedokan | I18: PAKAI | J18: 16-07-2019 | K18: 00051 | L18: PERTANIAN | M18: Tanah Milik Adat | N18: =F18*103000 -> 10197000 | O18: OO | P18: Tanah Pertanian
A19: =A18+1 -> 7 | B19: TANAH KAS DESA | F19: 2871 | G19: 1960 | H19: Kedokan | I19: PAKAI | J19: 16-07-2019 | K19: 00050 | L19: PERTANIAN | M19: Tanah Milik Adat | N19: =F19*103000 -> 295713000 | O19: OO | P19: Tanah Pertanian
A20: =A19+1 -> 8 | B20: TANAH KAS DESA | F20: 1646 | G20: 1960 | H20: Karanganyar | I20: PAKAI | L20: Sekolah | M20: Tanah Milik Adat | N20: =F20*103000 -> 169538000 | O20: SD Klego I | P20: Tanah Untuk Bangunan Gedung
A21: =A20+1 -> 9 | B21: TANAH KAS DESA | F21: 41 | G21: 1960 | H21: Karanganyar | I21: PAKAI | L21: Sarana Umum | M21: Tanah Milik Adat | N21: =F21*103000 -> 4223000 | O21: OO | P21: Tanah Penggunaan Lainnya
A22: =A21+1 -> 10 | B22: TANAH KAS DESA | F22: 1322 | G22: 1960 | H22: Klego | I22: PAKAI | J22: 16-07-2019 | K22: 00049 | L22: Sekolah | M22: C. 319 Ps 92a S II Seb | N22: =F22*103000 -> 136166000 | O22: SD Klego II | P22: Tanah Untuk Bangunan Gedung
A23: =A22+1 -> 11 | B23: TANAH KAS DESA | F23: 590 | G23: 1960 | H23: Klego | I23: PAKAI | J23: 16-07-2019 | K23: 00048 | L23: Kantor | M23: C. 319 Ps 47 SL.V Seb | N23: =F23*103000 -> 60770000 | O23: Koramil | P23: Tanah Untuk Bangunan Gedung
A24: =A23+1 -> 12 | B24: TANAH KAS DESA | F24: 4081 | G24: 1960 | H24: Klego | I24: PAKAI | J24: 23-08-2019 | K24: 00086 | L24: PERTANIAN | M24: Tanah Milik Adat | N24: =F24*103000 -> 420343000 | O24: Ex Bengkok Kesra | P24: Tanah Pertanian
A25: =A24+1 -> 13 | B25: TANAH KAS DESA | F25: 1901 | G25: 1960 | H25: Klalingan | I25: PAKAI | J25: 31-07-2019 | K25: 00083 | L25: PERTANIAN | M25: Tanah Milik Adat | N25: =F25*103000 -> 195803000 | O25: Ex Bengkok Kadus IV | P25: Tanah Pertanian
A26: =A25+1 -> 14 | B26: TANAH KAS DESA | F26: 7446 | G26: 1960 | H26: Klalingan | I26: PAKAI | J26: 23-08-2019` | K26: 00085 | L26: PERTANIAN | M26: Tanah Milik Adat | N26: =F26*103000 -> 766938000 | O26: Ex Bengkok Kades | P26: Tanah Pertanian
A27: =A26+1 -> 15 | B27: TANAH KAS DESA | F27: 2941 | G27: 1960 | H27: Ngembat | I27: PAKAI | J27: 04-06-2019` | K27: 00044 | L27: Lapangan | M27: C. 1 Ps. 142a-27 S. V | N27: =F27*103000 -> 302923000 | O27: Kas Desa | P27: Tanah Penggunaan Lainnya
A28: =A27+1 -> 16 | B28: TANAH KAS DESA | F28: 5623 | G28: 1960 | H28: Ngembat | I28: PAKAI | J28: 04-06-2019` | K28: 00042 | L28: Makam | M28: C. 1 Ps. 141a-29 S. IV Seb | N28: =F28*103000 -> 579169000 | O28: Kas Desa | P28: Tanah Penggunaan Lainnya
A29: =A28+1 -> 17 | B29: TANAH KAS DESA | F29: 2099 | G29: 1960 | H29: Ngembat | I29: PAKAI | J29: 04-06-2019` | K29: 00043 | L29: Lapangan | M29: C. 1 Ps. 141b-26 S. V | N29: =F29*103000 -> 216197000 | O29: Kas Desa | P29: Tanah Penggunaan Lainnya
A30: =A29+1 -> 18 | B30: TANAH KAS DESA | F30: 1384 | G30: 1960 | H30: Ngembat | I30: PAKAI | J30: 04-06-2019` | K30: 00044 | L30: Lapangan | M30: C. 1 Ps. 142b-26 S. V | N30: =F30*103000 -> 142552000 | O30: Kas Desa | P30: Tanah Penggunaan Lainnya
A31: =A30+1 -> 19 | B31: TANAH KAS DESA | F31: 5720 | G31: 1960 | H31: Klego | I31: PAKAI | J31: 16-07-2019 | K31: 00047 | L31: Makam | M31: C. 319 Ps. 44 SL.II Seb | N31: =F31*103000 -> 589160000 | O31: Kas Desa | P31: Tanah Penggunaan Lainnya
A32: =A31+1 -> 20 | B32: TANAH KAS DESA | F32: 2944 | G32: 1960 | H32: Kedokan | I32: PAKAI | J32: 16-07-2019 | K32: 00046 | L32: PERTANIAN | M32: C. 317 Ps 135 SL. V Seb | N32: =F32*103000 -> 303232000 | O32: Ex Bengkok Kadus III | P32: Tanah Pertanian
A33: =A32+1 -> 21 | B33: TANAH KAS DESA | F33: 10710 | G33: 1960 | H33: Klego | I33: PAKAI | J33: 04-06-2019 | K33: 00039 | L33: PERTANIAN | M33: C. 314 Ps. 165 Sl.I Seb | N33: =F33*103000 -> 1103130000 | O33: Ex Bengkok Kades | P33: Tanah Pertanian
... A60: =A59+1 -> 48 | B60: TANAH KAS DESA | F60: 13070 | G60: 1960 | H60: Karanganyar | I60: PAKAI | J60: 25-05-2019 | K60: 00030 | L60: Pertanian | M60: C. 316 Ps. 128 Sl. I | N60: =F60*103000 -> 1346210000 | O60: Ex Bengkok Sekdes | P60: Tanah Pertanian
A61: =A60+1 -> 49 | B61: TANAH JALAN POROS DESA | F61: 5362.5 | G61: 1960 | H61: KLEGO-KARANGGATAK | I61: PAKAI | L61: JALAN | M61: Asal usul | N61: =F61*103000 -> 552337500 | P61: Tanah Perkampungan
A62: =A61+1 -> 50 | B62: TANAH JALAN POROS DESA | F62: 2000 | H62: KLEGO-BADE | I62: PAKAI | L62: JALAN | M62: Asal usul | N62: =F62*103000 -> 206000000 | P62: Tanah Perkampungan
A63: =A62+1 -> 51 | B63: TANAH JALAN POROS DESA | F63: 2537.5 | H63: KARANGANYAR RT 07-KLALINGAN | L63: JALAN | M63: Asal usul | N63: =F63*103000 -> 261362500 | P63: Tanah Perkampungan
A64: =A63+1 -> 52 | B64: TANAH JALAN POROS DESA | F64: 3664.5 | H64: KARANGANYAR RT 08-KLALINGAN | L64: JALAN | M64: Asal usul | N64: =F64*103000 -> 377443500 | P64: Tanah Perkampungan
A65: =A64+1 -> 53 | B65: TANAH JALAN POROS DESA | F65: 6325 | H65: KLEGO-GONDANGLEGI | L65: JALAN | M65: Asal usul | N65: =F65*103000 -> 651475000 | P65: Tanah Perkampungan
A66: =A65+1 -> 54 | B66: TANAH JALAN POROS DESA | F66: 7811 | H66: NGEMBAT-KEDOKAN | L66: JALAN | M66: Asal usul | N66: =F66*103000 -> 804533000 | P66: Tanah Perkampungan
A67: =A66+1 -> 55 | B67: TANAH JALAN POROS DESA | F67: 1612 | H67: KEDOKAN-PENGKOL | L67: JALAN | M67: Asal usul | N67: =F67*103000 -> 166036000 | P67: Tanah Perkampungan
A68: =A67+1 -> 56 | B68: TANAH JALAN RT 01 | F68: 3870 | G68: 1960 | H68: KLEGO RT 01 | I68: PAKAI | L68: JALAN | M68: Asal usul | N68: =F68*103000 -> 398610000 | P68: Tanah Perkampungan
...

Sheet Peralatan Mesin
A2: VALIDASI KARTU INVENTARIS PERALATAN DAN MESIN PERALATAN DAN MESIN (ALAT ANGKUT)
A3: DATA HASIL INVENTARISASI INSPEKTORAT S/D 2018
B4: Provinsi | C4: Jawa Tengah
B5: Kab./Kota | C5: Boyolali
B6: Kecamatan | C6: Klego
B7: Desa | C7: Klego
A10: No. | B10: Jenis Barang / Nama Barang | D10: Jumlah | E10: N o m o r | G10: Merk/ Type | H10: Ukuran/ CC | I10: Bahan | J10: Tahun Pembelian | O10: Asal- usul | P10: Harga (ribuan Rp) | Q10: Kondisi (R,KB,RB, hilang) | R10: Keterangan | S10: DI ISI SESUAI RINCIAN SISKEUDES
E11: Kode Barang | F11: Register | K11: Rangka | L11: Mesin | M11: Polisi | N11: BPKB
A12: 1 | B12: 2 | D12: 3 | E12: 4 | F12: 5 | G12: 6 | H12: 7 | I12: 8 | J12: 10 | K12: 11 | L12: 12 | M12: 13 | N12: 14 | O12: 15 | P12: 16 | Q12: 17 | R12: 18
A13: 1 | B13: MEJA KERJA | D13: 14 | I13: Kayu | J13: 2009 | O13: pembelian | P13: 5500000 | Q13: BAIK | S13: Alat Kantor dan Rumah Tangga
A14: =A13+1 -> 2 | B14: MEJA LIPAT | D14: 5 | I14: campuran | J14: 2019 | O14: pembelian | P14: 1500000 | Q14: BAIK | S14: Alat Kantor dan Rumah Tangga
A15: =A14+1 -> 3 | B15: MEJA RAPAT | D15: 4 | I15: Kayu | J15: 2015 | O15: pembelian | P15: 2000000 | Q15: KB | S15: Alat Kantor dan Rumah Tangga
A16: =A15+1 -> 4 | B16: MEJA PING-PONG | D16: 1 | I16: Kayu | J16: 2016 | O16: pembelian | P16: 2500000 | Q16: BAIK | S16: Alat Kantor dan Rumah Tangga
A17: =A16+1 -> 5 | B17: ALMARI BESAR | D17: 3 | I17: Kayu | J17: 2009 | O17: pembelian | P17: 2500000 | Q17: BAIK | S17: Alat Kantor dan Rumah Tangga
A18: =A17+1 -> 6 | B18: TELEVISI | D18: 1 | G18: THOSIBA | H18: 29" | I18: campuran | J18: 2016 | O18: pembelian | P18: 2000000 | Q18: RB | S18: Alat Studio, Kominikasi dan Pemancar
A19: =A18+1 -> 7 | B19: VCD PLAYER | D19: 1 | G19: VISICOM | I19: campuran | J19: 2016 | O19: pembelian | P19: 350000 | Q19: KB | S19: Alat Studio, Kominikasi dan Pemancar
A20: =A19+1 -> 8 | B20: RADIO TAPE/WIRELLES | D20: 1 | G20: TENS | I20: campuran | J20: 2010 | O20: pembelian | P20: 600000 | Q20: BAIK | S20: Alat Studio, Kominikasi dan Pemancar
A21: =A20+1 -> 9 | B21: SPIKER AKTIF | D21: 1 | G21: BIG BASS | I21: campuran | J21: 2016 | O21: pembelian | P21: 1300000 | Q21: BAIK | S21: Alat Studio, Kominikasi dan Pemancar
A22: =A21+1 -> 10 | B22: SPEAKER AKTIF + AMPLIFIRE | D22: 1 | G22: ALPHA | I22: campuran | J22: 2017 | O22: pembelian | P22: 20000000 | Q22: BAIK | S22: Alat Studio, Kominikasi dan Pemancar
A23: =A22+1 -> 11 | B23: KIPAS ANGIN | D23: 2 | G23: MASPION | I23: campuran | J23: 2017 | O23: pembelian | P23: 900000 | Q23: BAIK | S23: Alat Kantor dan Rumah Tangga
A24: =A23+1 -> 12 | B24: KIPAS ANGIN | D24: 1 | G24: MIYAKO | I24: campuran | J24: 2015 | O24: pembelian | P24: 150000 | Q24: RB | S24: Alat Kantor dan Rumah Tangga
A25: =A24+1 -> 13 | B25: SEPEDA MOTOR | D25: 1 | G25: SUZUKI/ FV 110 LB | H25: 113 | I25: campuran | J25: 30-10- 2013 | K25: MH8BF46AADJ-114624 | L25: AEP1-ID-114752 | M25: AD 9705 JD | O25: pembelian | P25: 13000000 | Q25: KURANG BAIK | R25: BARANG DI GUNAKAN UNTUK OPERASIONAL KEPALA DESA | S25: Alat Angkutan
A26: =A25+1 -> 14 | B26: KURSI KERJA | D26: 12 | G26: BROTHER | I26: campuran | J26: 2018 | O26: pembelian | P26: 9600000 | Q26: BAIK | S26: Alat Kantor dan Rumah Tangga
A27: =A26+1 -> 15 | B27: KOMPUTER | D27: 2 | G27: SAMSUNG | I27: campuran | J27: 2015 | O27: pembelian | P27: 5000000 | Q27: RUSAK | S27: Komputer
A28: =A27+1 -> 16 | B28: KURSI RAPAT | D28: 60 | G28: FUTURA | I28: campuran | J28: 2018 | O28: pembelian | P28: 22500000 | Q28: BAIK | S28: Alat Kantor dan Rumah Tangga
A29: =A28+1 -> 17 | B29: KURSI HADAP | D29: 1 | I29: campuran | J29: 2015 | O29: pembelian | P29: 1500000 | Q29: BAIK | S29: Alat Kantor dan Rumah Tangga
A30: =A29+1 -> 18 | B30: PRINTER | D30: 1 | G30: Canon IP 2770 | I30: campuran | J30: 2015 | O30: pembelian | P30: 750000 | Q30: RUSAK | S30: Komputer
A31: =A30+1 -> 19 | B31: PRINTER | D31: 1 | G31: HP 2130 | I31: campuran | J31: 2016 | O31: pembelian | P31: 750000 | Q31: RUSAK | S31: Komputer
A32: =A31+1 -> 20 | B32: PRINTER | D32: 1 | G32: Canon IP 1700 | I32: campuran | J32: 2015 | O32: pembelian | P32: 400000 | Q32: RUSAK | S32: Komputer
A33: =A32+1 -> 21 | B33: LAPTOP | D33: 2 | G33: HP | I33: campuran | J33: 2018 | O33: pembelian | P33: 7000000 | Q33: BAIK | S33: Komputer
A34: =A33+1 -> 22 | B34: LAPTOP | D34: 1 | G34: ASSUS | I34: campuran | J34: 2016 | O34: pembelian | P34: 3900000 | Q34: KB | S34: Komputer
A35: =A34+1 -> 23 | B35: LAPTOP | D35: 1 | G35: ACCER | I35: campuran | J35: 2015 | O35: Pembelian | P35: 4300000 | Q35: RB | S35: Komputer
A36: =A35+1 -> 24 | B36: KOMPUTERISASI DAN PRINTER | D36: 2 | G36: LENOVO TOUCHSCREEN | I36: campuran | J36: 2018 | O36: pembelian | P36: 36410000 | Q36: BAIK | S36: Komputer
A37: =A36+1 -> 25 | B37: PROYEKTOR | D37: 1 | G37: HITACHI | I37: campuran | J37: 2016 | O37: pembelian | P37: 5000000 | Q37: BAIK | S37: Alat Studio, Komunikasi dan Pemencar
A38: =A37+1 -> 26 | B38: INTERNET | D38: 1 | G38: PROTELINDO | H38: 4 Mbps | I38: campuran | J38: 2016 | O38: pembelian | P38: 15500000 | Q38: BAIK | S38: Alat Studio, Komunikasi dan Pemencar
A39: =A38+1 -> 27 | B39: KURSI SOFA | D39: 1 | I39: campuran | J39: 2016 | O39: pembelian | P39: 4500000 | Q39: BAIK | S39: Alat Kantor dan Rumah Tangga
A40: =A39+1 -> 28 | B40: ALMARI RAK BUKU | D40: 1 | I40: kayu | J40: 2009 | O40: pembelian | P40: 2000000 | Q40: BAIK | S40: Alat Kantor dan Rumah Tangga
A41: =A40+1 -> 29 | B41: FILLING KABINET | D41: 2 | G41: TOP | I41: Besi | J41: 2016 | O41: pembelian | P41: 3000000 | Q41: BAIK | S41: Alat Kantor dan Rumah Tangga
A42: =A41+1 -> 30 | B42: FILLING KABINET | D42: 1 | I42: Besi | J42: 2010 | O42: pembelian | P42: 1000000 | Q42: Hilang | S42: Alat Kantor dan Rumah Tangga
A43: =A42+1 -> 31 | B43: FILLING KABINET | D43: 1 | G43: NAPOLLY | I43: Plastik | J43: 2015 | O43: pembelian | P43: 200000 | Q43: BAIK | S43: Alat Kantor dan Rumah Tangga
...

Sheet Gedung Bangunan
A2: VALIDASI INVENTARIS BARANG GEDUNG BANGUNAN GEDUNG DAN BANGUNAN
A3: DATA HASIL INVENTARISASI INSPEKTORAT S/D 2018
B4: Provinsi | C4: : | D4: Jawa Tengah
B5: Kab./Kota | C5: : | D5: Boyolali
B6: Kecamatan | C6: : | D6: Klego
B7: Desa | C7: : | D7: Klego
A9: No. | B9: Jenis Barang / Nama Barang | D9: N o m o r | F9: Konstruksi Bangunan | H9: Luas Lantai (M2) | I9: Letak/Lokasi Alamat | J9: Dokumen Gedung | L9: Luas (M2) | M9: Status Tanah | N9: Kode Tanah | O9: Asal usul | P9: Harga (ribuan Rp) | Q9: Kondisi bangunan (B,KB,RB) | R9: Keterangan | S9: DI ISI SESUAI RINCIAN SISKEUDES
D10: Kode Barang | E10: Register | F10: Bertingkat / Tidak | G10: Beton/ Tidak | J10: Tanggal | K10: Nomor
A11: 1 | B11: 2 | D11: 3 | E11: 4 | F11: 5 | G11: 6 | H11: 7 | I11: 8 | J11: 9 | K11: 10 | L11: 11 | M11: 12 | N11: 13 | O11: 14 | P11: 15 | Q11: 16 | R11: 17
A12: 1 | B12: KANTOR DESA | F12: TIDAK | G12: PERMANEN | H12: 174 | I12: KLEGO | J12: 2013 | L12: 5515 | M12: KAS DESA | P12: 400000000 | Q12: B | S12: Bangunan Gedung Kantor
A13: =A12+1 -> 2 | B13: BALE DESA | F13: TIDAK | G13: SEMI PERMANEN | H13: 72 | I13: KLEGO | J13: 2014 | L13: 5515 | M13: KAS DESA | P13: 100000000 | Q13: KB | S13: Bangunan Gedung Pertemuan
A14: =A13+1 -> 3 | B14: PAGAR | F14: TIDAK | G14: BETON | H14: 11.2 | I14: KLEGO | J14: 2015 | L14: 5515 | M14: KAS DESA | P14: 40000000 | Q14: B | S14: Bangunan Gedung Kantor
A15: =A14+1 -> 4 | B15: RUMAH DINAS DOKTER | F15: TIDAK | G15: PERMANEN | H15: 84 | I15: KLEGO | J15: 1995 | L15: 5515 | M15: KAS DESA | O15: Hibah | P15: 15000000 | Q15: KB | S15: Bangunan Kesehatan | X15: =P12+P14+P17+P30 -> 479024000
A16: =A15+1 -> 5 | B16: KIOS DESA | F16: TIDAK | G16: PERMANEN | H16: 84 | I16: KLEGO | J16: 2013 | L16: 5515 | M16: KAS DESA | O16: Hibah | P16: 105000000 | Q16: B | S16: Bangunan Gedung Pertokoan/Koperasi/Pasar
A17: =A16+1 -> 6 | B17: POS KEAMANAN | F17: TIDAK | G17: PERMANEN | H17: 15 | I17: KLEGO | J17: 2015 | L17: 5515 | M17: KAS DESA | P17: 25000000 | Q17: B | S17: Bangunan Gedung Kantor
A18: =A17+1 -> 7 | B18: TEMPAT PARKIR | F18: TIDAK | G18: SEMI PERMANEN | H18: 71 | I18: KLEGO | J18: 2017 | L18: 5515 | M18: KAS DESA | P18: 12500000 | Q18: B | S18: Bangunan Parkir
A19: =A18+1 -> 8 | B19: MUSHOLA | F19: TIDAK | G19: PERMANEN | H19: 16 | I19: KLEGO | J19: 2018 | L19: 5515 | M19: KAS DESA | O19: ADD | P19: 33688000 | Q19: B | S19: Bangunan Gedung Tempat Ibadah
A20: =A19+1 -> 9 | B20: KAMAR MANDI | F20: TIDAK | G20: PERMANEN | H20: 7 | I20: KLEGO | J20: 2013 | L20: 5515 | M20: KAS DESA | P20: 7500000 | Q20: B | S20: Bangunan Fasilitas Umum
B21: JUMLAH | P21: =SUM(P12:P20) -> 738688000
A23: DATA DARI BELANJA MODAL TAHUN 2019 (LAPORAN REALISASI ANGGARAN) KALAU ADA
A24: =A20+1 -> 10 | B24: REHAB KAMAR MANDI | F24: TIDAK | G24: PERMANEN | H24: 7 | I24: KLEGO | J24: 2019 | L24: 5515 | M24: KAS DESA | P24: 24008000 | Q24: B | S24: Bangunan Fasilitas Umum
A25: =A24+1 -> 11
B26: JUMLAH | P26: =SUM(P24:P25) -> 24008000
A28: DATA DARI BELANJA MODAL TAHUN 2020 (LAPORAN REALISASI ANGGARAN) KALAU ADA
A29: =A26+1 -> 1 | B29: Pembangunan Gedung TK | F29: TIDAK | G29: PERMANEN | I29: KLEGO | J29: 2020 | M29: KAS DESA | P29: 12056500 | Q29: B | S29: Bangunan Gedung Tempat Pendidikan
A30: =A29+1 -> 2 | B30: Pengadaaan Kanopi Bale Desa | F30: TIDAK | G30: PERMANEN | I30: KLEGO | J30: 2020 | M30: KAS DESA | P30: =13124000+900000 -> 14024000 | Q30: B | S30: Bangunan Gedung Kantor
B32: JUMLAH | P32: =SUM(P29:P31) -> 26080500
A34: DATA DARI BELANJA MODAL TAHUN 2021 (LAPORAN REALISASI ANGGARAN) KALAU ADA
B37: JUMLAH 2021 | P37: 0
A39: DATA DARI BELANJA MODAL TAHUN 2022 (LAPORAN REALISASI ANGGARAN) KALAU ADA
A40: 1 | B40: Talud Timur Parkiran | F40: TIDAK | G40: PERMANEN | I40: KLEGO | J40: 2022 | M40: KAS DESA | P40: 14240000 | Q40: B | S40: Bangunan Parkir
A41: 2 | B41: Rehap Mushola | F41: TIDAK | G41: PERMANEN | I41: KLEGO | J41: 2022 | M41: KAS DESA | P41: 7600000 | Q41: B | S41: Bangunan Gedung Tempat Ibadah
A42: 3 | B42: Keramik Pendopo | F42: TIDAK | G42: PERMANEN | I42: KLEGO | J42: 2022 | M42: KAS DESA | P42: 17410000 | Q42: B | S42: Bangunan Gedung Kantor
A43: 4 | B43: Pengadaan Grill Penutup Selokan | F43: TIDAK | G43: TIDAK PERMANEN | H43: 35.83 | I43: KLEGO | J43: 2022 | M43: KAS DESA | P43: 10750000 | Q43: B | S43: Bangunan Gedung Kantor
B45: JUMLAH 2022 | P45: =SUM(P40:P44) -> 50000000
A46: TOTAL | P46: =P21+P26+P32+P37+P45 -> 838776500
A48: DATA DARI BELANJA MODAL TAHUN 2023 (LAPORAN REALISASI ANGGARAN) KALAU ADA
A49: 1
A50: 2
A51: 3
...

Sheet Jalan Jembatan Irigasi
A2: VALIDASI INVENTARIS JALAN, JEMBATAN DAN IRIGASI JALAN, IRIGASI DAN JARINGAN
A3: DATA HASIL INVENTARISASI INSPEKTORAT S/D 2018
B4: Provinsi | E4: ='Aset Tetap Lainnya'!D4 -> : Jawa Tengah
B5: Kab./Kota | E5: ='Aset Tetap Lainnya'!D5 -> : Boyolali
B6: Kecamatan | E6: ='Aset Tetap Lainnya'!D6 -> : Klego
B7: Desa | E7: ='Aset Tetap Lainnya'!D7 -> : Klego
A9: No. | B9: Jenis Barang / Nama Barang | D9: N o m o r | F9: Konstruksi | G9: Panjang (M) | H9: Lebar (M) | I9: tinggi | J9: Luas/vol (M3) | K9: Letak Alamat | L9: Dokumen | N9: Status Tanah | O9: Kode Tanah | P9: Asal- usul | Q9: Harga (ribuan Rp) | R9: Kondisi (B, KB, RB) | S9: Keterangan | T9: DI ISI SESUAI RINCIAN SISKEUDES
D10: Kode Barang | E10: Register | L10: Tanggal | M10: Nomor
A11: 1 | B11: 2 | D11: 3 | E11: 4 | F11: 5 | G11: 6 | H11: 7 | J11: 8 | K11: 9 | L11: 10 | M11: 11 | N11: 12 | O11: 13 | P11: 14 | Q11: 15 | R11: 16 | S11: 17
A12: 1 | B12: Jembatan | F12: Permanen | G12: 10.5 | H12: 2.8 | I12: 0.4 | J12: =G12*H12*I12 -> 11.76 | K12: Klalingan | L12: 1999 | N12: Hibah | P12: Hibah | Q12: 85000000 | R12: KB | T12: Jembatan
A13: 2 | B13: Jalan Rabat Beton Klego | F13: Permanen | G13: 108 | H13: 3 | I13: 0.1 | J13: =G13*H13*I13 -> 32.4 | K13: RT 01 | L13: 2013 | N13: Hibah | P13: Hibah | Q13: 7000000 | R13: KB | T13: Jalan
A14: 3 | B14: Jalan Rabat Beton Klego | F14: Permanen | G14: 381 | H14: 3 | I14: 0.1 | J14: =G14*H14*I14 -> 114.3 | K14: RT 02 | L14: 2008 | N14: Hibah | P14: Hibah | Q14: 25000000 | R14: KB | T14: Jalan
A15: 4 | B15: Jalan Rabat Beton Klego | F15: Permanen | G15: 388 | H15: 3 | I15: 0.1 | J15: =G15*H15*I15 -> 116.4 | K15: RT 03 | L15: 2012 | N15: Hibah | P15: Hibah | Q15: 30000000 | R15: KB | T15: Jalan
A16: 5 | B16: Jalan Rabat Beton Klego | F16: Permanen | G16: 78 | H16: 3 | I16: 0.1 | J16: =G16*H16*I16 -> 23.4 | K16: RT 04 | L16: 2013 | N16: Hibah | P16: Hibah | Q16: 10000000 | R16: B | T16: Jalan
A17: 6 | B17: Jalan Rabat Beton Klego | F17: Permanen | G17: 422 | H17: 3 | I17: 0.1 | J17: =G17*H17*I17 -> 126.6 | K17: RT 05 | L17: 2009 | N17: Hibah | P17: Hibah | Q17: 25000000 | R17: B | T17: Jalan
A18: 7 | B18: Jalan Rabat Beton Klego | F18: Permanen | G18: 128 | H18: 3 | I18: 0.1 | J18: =G18*H18*I18 -> 38.4 | K18: RT 05 | L18: 2012 | N18: Hibah | P18: Hibah | Q18: 12500000 | R18: B | T18: Jalan
A19: 8 | B19: Jalan Rabat Beton Klego | F19: Permanen | G19: 164 | H19: 3 | I19: 0.1 | J19: =G19*H19*I19 -> 49.2 | K19: RT 05 | L19: 2013 | N19: Hibah | P19: BANKEUKAB | Q19: 20000000 | R19: KB | T19: Jalan
A20: 9 | B20: Jalan Rabat Beton Klego | F20: Permanen | G20: 36 | H20: 2 | I20: 0.1 | J20: =G20*H20*I20 -> 7.2 | K20: RT 06 | L20: 2010 | N20: Hibah | P20: Hibah | Q20: 7000000 | R20: KB | T20: Jalan
A21: 10 | B21: Jalan Rabat Beton Karanganyar | F21: Permanen | G21: 176 | H21: 2 | I21: 0.1 | J21: =G21*H21*I21 -> 35.2 | K21: RT 07 | L21: 2010 | N21: Hibah | P21: Hibah | Q21: 17000000 | R21: B | T21: Jalan
A22: 11 | B22: Jalan Rabat Beton Karanganyar | F22: Permanen | G22: 60 | H22: 2.5 | I22: 0.1 | J22: =G22*H22*I22 -> 15 | K22: RT 07 | L22: 2005 | N22: Hibah | P22: Hibah | Q22: 3000000 | R22: RB | T22: Jalan
A23: 12 | B23: Jalan Rabat Beton Karanganyar | F23: Permanen | G23: 271 | H23: 2.5 | I23: 0.1 | J23: =G23*H23*I23 -> 67.75 | K23: RT 08 | L23: 2010 | N23: Hibah | P23: Hibah | Q23: 21000000 | R23: RB | T23: Jalan
... A45: 34 | B45: Jalan Rabat Beton Kedokan | F45: Permanen | G45: 40 | H45: 3 | I45: 0.1 | J45: =G45*H45*I45 -> 12 | K45: RT 16 | L45: 2016 | N45: Hibah | P45: Hibah | Q45: 5000000 | R45: B | T45: Jalan
A46: 35 | B46: Jalan Rabat Beton Kedokan | G46: 110 | H46: 2.5 | I46: 0.1 | J46: =G46*H46*I46 -> 27.5 | K46: RT 16 | L46: 2016 | N46: Hibah | P46: Hibah | Q46: 15000000 | R46: B | T46: Jalan
A47: 36 | B47: Jalan Rabat Beton Kedokan | G47: 45 | H47: 2 | I47: 0.1 | J47: =G47*H47*I47 -> 9 | K47: RT 19 | L47: 2012 | N47: Hibah | P47: Hibah | Q47: 5000000 | R47: B | T47: Jalan
A48: 37 | B48: Jalan Rabat Beton Kedokan | G48: 92.4 | H48: 3 | I48: 0.1 | J48: =G48*H48*I48 -> 27.72 | K48: RT 19 | L48: 2013 | N48: Hibah | P48: Hibah | Q48: 3000000 | R48: RB | T48: Jalan
A49: 38 | B49: Jalan Rabat Beton Kedokan | G49: 157.6 | H49: 2 | I49: 0.1 | J49: =G49*H49*I49 -> 31.52 | K49: RT 20 | L49: 2016 | N49: Hibah | P49: Hibah | Q49: 22000000 | R49: KB | T49: Jalan
A50: 39 | B50: Jalan Rabat Beton Kedokan | G50: 115 | H50: 2.5 | I50: 0.1 | J50: =G50*H50*I50 -> 28.75 | K50: RT 21 | L50: 2018 | N50: Hibah | P50: Hibah | Q50: 17000000 | R50: B | T50: Jalan
A51: 40 | B51: Jalan Rabat Beton Klalingan | G51: 30 | H51: 2.5 | I51: 0.1 | J51: =G51*H51*I51 -> 7.5 | K51: RT 23 | L51: 2010 | N51: Hibah | P51: Hibah | Q51: 3500000 | R51: RB | T51: Jalan
A52: 41 | B52: Jalan Rabat Beton Klalingan | G52: 243 | H52: 2.5 | I52: 0.1 | J52: =G52*H52*I52 -> 60.75 | K52: RT 23, 24 | L52: 2016 | N52: Hibah | P52: DD | Q52: 51637500 | R52: B | T52: Jalan
A53: 42 | B53: Jalan Rabat Beton Klalingan | G53: 50.4 | H53: 2 | I53: 0.1 | J53: =G53*H53*I53 -> 10.08 | K53: RT 24 | L53: 2013 | N53: Hibah | P53: Hibah | Q53: 8500000 | R53: KB | T53: Jalan
A54: 43 | B54: Jalan Rabat Beton Klalingan | F54: Permanen | G54: 45 | H54: 2 | I54: 0.1 | J54: =G54*H54*I54 -> 9 | K54: RT 23 | L54: 2018 | N54: Hibah | P54: BANKEUKAB | Q54: 16560550 | R54: BAIK | T54: Jalan
A55: 44 | B55: Jalan Rabat Beton Karanganyar | F55: Permanen | G55: 175 | H55: 2.5 | I55: 0.1 | J55: =G55*H55*I55 -> 43.75 | K55: RT 07 | L55: 2018 | N55: Hibah | P55: DD | Q55: 34512200 | R55: BAIK | T55: Jalan
A56: 45 | B56: Jalan Rabat Beton Klego | F56: Permanen | G56: 104 | H56: 2.5 | I56: 0.1 | J56: =G56*H56*I56 -> 26 | K56: RT 01 | L56: 2018 | N56: Hibah | P56: BANKEUKAB | Q56: 31118650 | R56: BAIK | T56: Jalan
A57: 46 | B57: Jalan Rabat Beton Klego | F57: Permanen | G57: 56 | H57: 3 | I57: 0.1 | J57: =G57*H57*I57 -> 16.8 | K57: RT 04 | L57: 2018 | N57: Hibah | P57: DD | Q57: 19257750 | R57: BAIK | T57: Jalan
A58: 47 | B58: Jalan Aspal Karanganyar | F58: Permanen | G58: 398 | H58: 3 | I58: 0.05 | J58: =G58*H58*I58 -> 59.7 | K58: RT 08 | L58: 2018 | N58: Hibah | P58: DD | Q58: 75000000 | R58: BAIK | T58: Jalan
A59: 48 | B59: Jalan Aspal Poros Desa Dukuh Karanganyar - Klalingan | F59: Permanen | G59: 1079 | H59: 3 | I59: 0.03 | J59: =G59*H59*I59 -> 97.11 | K59: RT 08 - Klalingan | L59: 2018 | N59: Hibah | P59: DD | Q59: 294386500 | R59: BAIK | T59: Jalan
A60: 49 | B60: Jalan Aspal Poros Desa Dukuh Ngembat - Kedokan | F60: Permanen | G60: 490 | H60: 3 | I60: 0.05 | J60: =G60*H60*I60 -> 73.5 | K60: Dusun Ngembat RT 13, 14 | L60: 2018 | N60: Hibah | P60: DD | Q60: 109064250 | R60: BAIK | T60: Jalan
A61: 50 | B61: Jalan Rabat Beton Poros Desa Dukuh Kedokan | F61: Permanen | G61: 138.5 | H61: 4 | I61: 0.1 | J61: =G61*H61*I61 -> 55.4 | K61: RT 18, 19 | L61: 2018 | N61: Hibah | P61: DD | Q61: 48847500 | R61: BAIK | T61: Jalan
A62: 51 | B62: Jalan Rabat Beton Kedokan | F62: Permanen | G62: 140 | H62: 2.5 | I62: 0.1 | J62: =G62*H62*I62 -> 35 | K62: RT 14, 16 | L62: 2018 | N62: Hibah | P62: DD | Q62: 58087250 | R62: BAIK | T62: Jalan
A63: 52 | B63: Jalan Rabat Beton Kedokan | F63: Permanen | G63: 50 | H63: 4 | I63: 0.1 | J63: =G63*H63*I63 -> 20 | K63: RT 15 | L63: 2018 | N63: Hibah | P63: DD | Q63: 12931000 | R63: BAIK | T63: Jalan
...

Sheet Aset Tetap Lainnya
A2: VALIDASI KARTU INVENTARIS ASET TETAP LAINNYA ASET TETAP LAINNYA
A3: DATA HASIL INVENTARISASI INSPEKTORAT S/D 2018
B4: Provinsi | D4: : Jawa Tengah
B5: Kab./Kota | D5: : Boyolali
B6: Kecamatan | D6: : Klego
B7: Desa | D7: : Klego
A9: No. | B9: Jenis Barang /Nama Barang | D9: Kode Barang | E9: Nomor Register | F9: Buku / Perpustakaan | H9: Barang Bercorak Kesenian / Kebudayaan | K9: Hewan/Ternak dan Tumbuhan | N9: Asal usul | O9: Tahun Cetak / Pembelian | P9: Harga (ribuan Rp) | Q9: Kondisi (B, KB, RB) | R9: Keterangan | S9: DI ISI SESUAI RINCIAN SISKEUDES
F10: Judul/ Pencipta | G10: Spesifikasi | H10: Asal | I10: Pencipta | J10: Bahan | K10: Jenis | L10: Ukuran | M10: Jumlah
A11: 1 | B11: 2 | D11: 3 | E11: 4 | F11: 5 | G11: 6 | H11: 7 | I11: 8 | J11: 9 | K11: 10 | L11: 11 | M11: 12 | N11: 13 | O11: 14 | P11: 15 | R11: 16
A12: 1 | B12: POHON JATI | L12: 90 | M12: 20 | P12: 2000000 | R12: Tanah OO | S12: Tanaman
A13: =A12+1 -> 2 | B13: POHON AKASIA | L13: 80 | M13: 20 | P13: 2000000 | R13: Tanah OO | S13: Tanaman
A14: =A13+1 -> 3 | B14: POHON BIBIS | L14: 300 | M14: 1 | P14: 200000 | R14: Sumur Padas | S14: Tanaman
A15: =A14+1 -> 4 | B15: POHON SEMBOJA | L15: 60 | M15: 20 | P15: 3000000 | R15: Makam Klego dan Ngembat | S15: Tanaman
A16: =A15+1 -> 5 | B16: POHON KEPOH | L16: 270 | M16: 4 | P16: 500000 | R16: Sumur Bulu | S16: Tanaman
A17: =A16+1 -> 6 | B17: POHON KARET | L17: 90 | M17: 40 | P17: 300000 | R17: Makam Klego dan Ngembat | S17: Tanaman
A18: =A17+1 -> 7 | B18: POHON BERINGIN | L18: 260 | M18: 1 | P18: 800000 | R18: Sumur Jengglong | S18: Tanaman
A19: =A18+1 -> 8 | B19: POHON RANDU ALAS | L19: 350 | M19: 3 | P19: 900000 | R19: Makam Ngembat | S19: Tanaman
A20: =A19+1 -> 9 | B20: Buku C Desa | P20: 1000 | S20: Bahan Perpustakaan
B21: JUMLAH | P21: =SUM(P12:P20) -> 9701000
A23: DATA DARI BELANJA MODAL TAHUN 2019 (LAPORAN REALISASI ANGGARAN) KALAU ADA
A24: =A20+1 -> 10 | B24: Peta Digital | O24: 2019 | P24: 29480000 | S24: Bahan Perpustakaan
A25: =A24+1 -> 11 | S25: ……………..
A26: =A25+1 -> 12 | S26: ……………..
A27: =A26+1 -> 13 | S27: ……………..
A28: =A27+1 -> 14 | S28: ……………..
A29: =A28+1 -> 15 | S29: ……………..
A30: =A29+1 -> 16 | S30: ……………..
A31: =A30+1 -> 17 | S31: ……………..
A32: JUMLAH | P32: =SUM(P24:P31) -> 29480000
A34: DATA DARI BELANJA MODAL TAHUN 2020 (LAPORAN REALISASI ANGGARAN) KALAU ADA
A35: =A31+1 -> 18 | P35: 0
S36: ……………..
A37: JUMLAH | P37: =SUM(P35:P36) -> 0
A38: DATA DARI BELANJA MODAL TAHUN 2021 (LAPORAN REALISASI ANGGARAN) KALAU ADA
A39: 19 | P39: 0
A40: JUMLAH | P40: =SUM(P39) -> 0
A42: DATA DARI BELANJA MODAL TAHUN 2022 (LAPORAN REALISASI ANGGARAN) KALAU ADA
A43: 20 | P43: 0
A44: JUMLAH | P44: =SUM(P43) -> 0
A45: TOTAL | P45: =P21+P32+P37+P40+P44 -> 39181000 | T45: =9701000 -> 9701000
...

Sheet Rekap Aset Tetap
A2: PEMERINTAH DESA KLEGO
A3: PENAMBAH DAN PENGURANG ASET TETAP
A4: PER 31 DESEMBER 2025
A7: NO | B7: URAIAN | C7: SALDO AWAL sampai dengan 2018 (hasil Inventarisasi) | D7: Tahun 2019 (sesuai LRA 2019) | F7: SALDO AWAL sampai dengan 2020 (hasil Inventarisasi) | G7: Tahun 2020 (Sesuai LRA 2020) | I7: SALDO AWAL sampai dengan 2021 (hasil Inventarisasi) | J7: Tahun 2021 (Sesuai LRA 2021) | L7: SALDO AKHIR 2021 | M7: SALDO AWAL sampai dengan 2022 (hasil Inventarisasi) | N7: Tahun 2022 (Sesuai LRA 2022) | P7: SALDO AKHIR 2022 | Q7: SALDO AWAL sampai dengan 2023 (hasil Inventarisasi) | R7: Tahun 2023 (Sesuai LRA 2023) | T7: SALDO AKHIR 2023 | U7: SALDO AWAL sampai dengan 2024 (hasil Inventarisasi) | V7: Tahun 2024 (Sesuai LRA 2024) | X7: SALDO AKHIR 2024 | Y7: SALDO AWAL sampai dengan 2025 (hasil Inventarisasi) | Z7: Tahun 2025 (Sesuai LRA 2025) | AB7: SALDO AKHIR 2025
D8: Penambahan | E8: Pengurangan | G8: Penambahan | H8: Pengurangan | J8: Penambahan | K8: Pengurangan | N8: Penambahan | O8: Pengurangan | R8: Penambahan | S8: Pengurangan | V8: Penambahan | W8: Pengurangan | Z8: Penambahan | AA8: Pengurangan
A9: 1 | B9: 2 | C9: 3 | D9: 4 | E9: 5 | F9: 6=3+4-5 | G9: 7 | H9: 8 | I9: 9=6+7-8 | J9: 10 | K9: 11 | L9: 12=9+10-11 | M9: 10=9+10-11 | N9: 11 | O9: 12 | P9: 12=10+11-12 | Q9: 10=9+10-11 | R9: 11 | S9: 12 | T9: 12=10+11-12 | U9: 10=9+10-11 | V9: 11 | W9: 12 | X9: 12=10+11-12 | Y9: 10=9+10-11 | Z9: 11 | AA9: 12 | AB9: 12=10+11-12
A11: 1 | B11: Tanah | C11: =Tanah!N92 -> 28670245600 | D11: 0 | E11: 0 | F11: =C11+D11-E11 -> 28670245600 | G11: 0 | H11: 0 | I11: =F11+G11-H11 -> 28670245600 | J11: 0 | K11: 0 | L11: =I11+J11-K11 -> 28670245600 | M11: =I11+J11-K11 -> 28670245600 | N11: 0 | O11: 0 | P11: =M11+N11-O11 -> 28670245600 | Q11: =M11+N11-O11 -> 28670245600 | R11: 0 | S11: 0 | T11: =Q11+R11-S11 -> 28670245600 | U11: =Q11+R11-S11 -> 28670245600 | V11: 0 | W11: 0 | X11: =U11+V11-W11 -> 28670245600 | Y11: =U11+V11-W11 -> 28670245600 | Z11: 0 | AA11: 0 | AB11: =Y11+Z11-AA11 -> 28670245600
A12: 2 | B12: Peralatan dan Mesin | C12: ='Peralatan Mesin'!P63 -> 195710000 | D12: ='Peralatan Mesin'!P73 -> 32500000 | E12: 0 | F12: =C12+D12-E12 -> 228210000 | G12: ='Peralatan Mesin'!P82 -> 37000000 | H12: 0 | I12: =F12+G12-H12 -> 265210000 | J12: ='Peralatan Mesin'!P87 -> 11700000 | K12: 0 | L12: =I12+J12-K12 -> 276910000 | M12: =I12+J12-K12 -> 276910000 | N12: ='Peralatan Mesin'!P94 -> 9665000 | O12: 0 | P12: =M12+N12-O12 -> 286575000 | Q12: =M12+N12-O12 -> 286575000 | R12: ='Peralatan Mesin'!P100 -> 284000000 | S12: 0 | T12: =Q12+R12-S12 -> 570575000 | U12: =Q12+R12-S12 -> 570575000 | V12: ='Peralatan Mesin'!P107 -> 18490000 | X12: =U12+V12-W12 -> 589065000 | Y12: =U12+V12-W12 -> 589065000 | Z12: ='Peralatan Mesin'!P115 -> 38150000 | AB12: =Y12+Z12-AA12 -> 627215000
A13: 3 | B13: Gedung dan Bangunan | C13: ='Gedung Bangunan'!P21 -> 738688000 | D13: ='Gedung Bangunan'!P26 -> 24008000 | E13: 0 | F13: =C13+D13-E13 -> 762696000 | G13: ='Gedung Bangunan'!P32 -> 26080500 | H13: 0 | I13: =F13+G13-H13 -> 788776500 | J13: ='Gedung Bangunan'!P37 -> 0 | K13: 0 | L13: =I13+J13-K13 -> 788776500 | M13: =I13+J13-K13 -> 788776500 | N13: ='Gedung Bangunan'!P45 -> 50000000 | O13: 0 | P13: =M13+N13-O13 -> 838776500 | Q13: =M13+N13-O13 -> 838776500 | R13: 0 | S13: 0 | T13: =Q13+R13-S13 -> 838776500 | U13: =Q13+R13-S13 -> 838776500 | V13: 0 | W13: 0 | X13: =U13+V13-W13 -> 838776500 | Y13: =U13+V13-W13 -> 838776500 | Z13: ='Gedung Bangunan'!P67 -> 14637500 | AA13: 0 | AB13: =Y13+Z13-AA13 -> 853414000
A14: 4 | B14: Jalan,Irigasi dan Jaringan | C14: ='Jalan Jembatan Irigasi'!Q65 -> 2050388422 | D14: ='Jalan Jembatan Irigasi'!Q90 -> 995988800 | E14: 0 | F14: =C14+D14-E14 -> 3046377222 | G14: ='Jalan Jembatan Irigasi'!Q106 -> 509989150 | H14: 0 | I14: =F14+G14-H14 -> 3556366372 | J14: ='Jalan Jembatan Irigasi'!Q130 -> 771418850 | K14: 0 | L14: =I14+J14-K14 -> 4327785222 | M14: =I14+J14-K14 -> 4327785222 | N14: ='Jalan Jembatan Irigasi'!Q143 -> 403902978 | O14: 0 | P14: =M14+N14-O14 -> 4731688200 | Q14: =M14+N14-O14 -> 4731688200 | R14: ='Jalan Jembatan Irigasi'!Q159 -> 622101900 | S14: 0 | T14: =Q14+R14-S14 -> 5353790100 | U14: =Q14+R14-S14 -> 5353790100 | V14: ='Jalan Jembatan Irigasi'!Q173 -> 747296750 | X14: =U14+V14-W14 -> 6101086850 | Y14: =U14+V14-W14 -> 6101086850 | Z14: ='Jalan Jembatan Irigasi'!Q197 -> 949288500 | AB14: =Y14+Z14-AA14 -> 7050375350
A15: 5 | B15: Aset Tetap Lainnya | C15: ='Aset Tetap Lainnya'!P21 -> 9701000 | D15: ='Aset Tetap Lainnya'!P32 -> 29480000 | E15: 0 | F15: =C15+D15-E15 -> 39181000 | G15: ='Aset Tetap Lainnya'!P37 -> 0 | H15: 0 | I15: =F15+G15-H15 -> 39181000 | J15: ='Aset Tetap Lainnya'!P40 -> 0 | K15: 0 | L15: =I15+J15-K15 -> 39181000 | M15: =I15+J15-K15 -> 39181000 | N15: ='Aset Tetap Lainnya'!P44 -> 0 | O15: 0 | P15: =M15+N15-O15 -> 39181000 | Q15: =M15+N15-O15 -> 39181000 | R15: ='Aset Tetap Lainnya'!T44 -> 0 | S15: 0 | T15: =Q15+R15-S15 -> 39181000 | U15: =Q15+R15-S15 -> 39181000 | V15: 0 | W15: 0 | X15: =U15+V15-W15 -> 39181000 | Y15: =U15+V15-W15 -> 39181000 | Z15: 0 | AA15: 0 | AB15: =Y15+Z15-AA15 -> 39181000
A16: 6 | B16: Konstruksi Dalam Pengerjaan | C16: 0 | D16: 0 | E16: 0 | F16: =C16+D16-E16 -> 0 | H16: 0 | K16: 0 | L16: =I16+J16-K16 -> 0 | O16: 0 | P16: =M16+N16-O16 -> 0 | S16: 0 | T16: =Q16+R16-S16 -> 0 | U16: =Q16+R16-S16 -> 0 | V16: 0 | W16: 0 | X16: =U16+V16-W16 -> 0 | Y16: =U16+V16-W16 -> 0 | Z16: 0 | AA16: 0 | AB16: =Y16+Z16-AA16 -> 0
A17: 7 | B17: Akumulasi Penyusutan | C17: 0 | D17: 0 | E17: 0 | F17: =C17+D17-E17 -> 0 | H17: 0 | K17: 0 | L17: =I17+J17-K17 -> 0 | O17: 0 | P17: =M17+N17-O17 -> 0 | S17: 0 | T17: =Q17+R17-S17 -> 0 | U17: =Q17+R17-S17 -> 0 | V17: 0 | W17: 0 | X17: =U17+V17-W17 -> 0 | Y17: =U17+V17-W17 -> 0 | Z17: 0 | AA17: 0 | AB17: =Y17+Z17-AA17 -> 0
B19: JUMLAH | C19: =SUM(C11:C17) -> 31664733022 | D19: =SUM(D11:D17) -> 1081976800 | E19: =SUM(E11:E17) -> 0 | F19: =SUM(F11:F17) -> 32746709822 | G19: =SUM(G11:G17) -> 573069650 | H19: =SUM(H11:H17) -> 0 | I19: =SUM(I11:I17) -> 33319779472 | J19: =SUM(J11:J17) -> 783118850 | L19: =SUM(L11:L18) -> 34102898322 | M19: =SUM(M11:M17) -> 34102898322 | N19: =SUM(N11:N17) -> 463567978 | P19: =SUM(P11:P18) -> 34566466300 | Q19: =SUM(Q11:Q17) -> 34566466300 | R19: =SUM(R11:R17) -> 906101900 | T19: =SUM(T11:T18) -> 35472568200 | U19: =SUM(U11:U18) -> 35472568200 | V19: =SUM(V11:V18) -> 765786750 | W19: =SUM(W11:W18) -> 0 | X19: =SUM(X11:X18) -> 36238354950 | Y19: =SUM(Y11:Y18) -> 36238354950 | Z19: =SUM(Z11:Z18) -> 1002076000 | AA19: =SUM(AA11:AA18) -> 0 | AB19: =SUM(AB11:AB18) -> 37240430950
V21: ='Aset Tetap Lainnya'!Q53 -> Desa Klego, 31 Desember 2025 | Z21: =V21 -> Desa Klego, 31 Desember 2025
V22: ='Aset Tetap Lainnya'!C55 -> Kepala Desa Klego | Z22: =V22 -> Kepala Desa Klego
B26: CATATAN : | V26: ='Aset Tetap Lainnya'!C59 -> GUNTUR HERU SUPRAPTO, S.Pd | Z26: =V26 -> GUNTUR HERU SUPRAPTO, S.Pd
B27: KOLOM 3 | C27: DI ISI JUMLAH DARI MASING-MASING SHEET ROW WARNA HIJAU
B28: KOLOM 4 | C28: DI ISI JUMLAH DARI MASING-MASING SHEET ROW WARNA KUNING
B29: Bila ada belanja operasional yg dikeluarkan atas pembentukan Belanja Modal yang masuk di anggaran
B30: barang dan jasa (karena kesalahan penganggaran) di tambahkan dalam Belanja Modal terkait dan perbedaan selisihnya di jelaskan
B31: dalam CaLK

Sheet RincianSiskeu
B2: ASET TANAH | D2: =SUM(D3:D16) -> 28670245600
B3: Belanja Modal Tanah | C3: Tanah Kas Desa
C4: Tanah Perkampungan | D4: =SUM(Tanah!N61:N91) -> 7703802600
C5: Tanah Pertanian | D5: =Tanah!N13+Tanah!N14+Tanah!N16+Tanah!N17+Tanah!N18+Tanah!N19+Tanah!N24+Tanah!N25+Tanah!N26+Tanah!N32+Tanah!N33+Tanah!N34+Tanah!N35+Tanah!N36+Tanah!N37+Tanah!N38+Tanah!N39+Tanah!N40+Tanah!N41+Tanah!N42+Tanah!N43+Tanah!N44+Tanah!N45+Tanah!N46+Tanah!N47+Tanah!N48+Tanah!N49+Tanah!N50+Tanah!N51+Tanah!N53+Tanah!N54+Tanah!N55+Tanah!N56+Tanah!N57+Tanah!N58+Tanah!N59+Tanah!N60 -> 17576048000
C6: Tanah Perkebunan
C7: Tanah Hutan
C8: Tanah Kebun Campuran
C9: Tanah Kolam Ikan
C10: Tanah Danau/Rawa
C11: Tanah Tandus/Rusak
C12: Tanah Alang-alang dan Padang Rumput
C13: Tanah Pertambangan
C14: Tanah untuk Bangunan Gedung | D14: =Tanah!N15+Tanah!N20+Tanah!N22+Tanah!N23+Tanah!N52 -> 1556171000
C15: Tanah untuk Bangunan Bukan Gedung
C16: Tanah Penggunaan Lainnya | D16: =Tanah!N21+Tanah!N27+Tanah!N28+Tanah!N29+Tanah!N30+Tanah!N31 -> 1834224000
B17: ASET PERALATAN DAN MESIN | D17: =SUM(D18:D37) -> 627215000
B18: Belanja Modal Peralatan Elektronik dan Alat Studio | C18: Alat Studio, Komunikasi dan Pemencar | D18: ='Peralatan Mesin'!P18+'Peralatan Mesin'!P19+'Peralatan Mesin'!P20+'Peralatan Mesin'!P21+'Peralatan Mesin'!P22+'Peralatan Mesin'!P37+'Peralatan Mesin'!P45+'Peralatan Mesin'!P53+'Peralatan Mesin'!P54+'Peralatan Mesin'!P55+'Peralatan Mesin'!P69+'Peralatan Mesin'!P93 -> 35090000
B19: Belanja Modal Peralatan Komputer | C19: Komputer | D19: ='Peralatan Mesin'!P27+'Peralatan Mesin'!P30+'Peralatan Mesin'!P31+'Peralatan Mesin'!P32+'Peralatan Mesin'!P33+'Peralatan Mesin'!P34+'Peralatan Mesin'!P35+'Peralatan Mesin'!P36+'Peralatan Mesin'!P47+'Peralatan Mesin'!P66+'Peralatan Mesin'!P67+'Peralatan Mesin'!P68+'Peralatan Mesin'!P78+'Peralatan Mesin'!P79+'Peralatan Mesin'!P85+'Peralatan Mesin'!P92+'Peralatan Mesin'!P105+'Peralatan Mesin'!P111+'Peralatan Mesin'!P112+'Peralatan Mesin'!P113 -> 172980000
B20: Belanja Modal Peralatan Mebelair dan Aksesoris Ruangan | C20: Alat Kantor dan Rumah Tangga | D20: ='Peralatan Mesin'!P13+'Peralatan Mesin'!P14+'Peralatan Mesin'!P15+'Peralatan Mesin'!P16+'Peralatan Mesin'!P17+'Peralatan Mesin'!P23+'Peralatan Mesin'!P24+'Peralatan Mesin'!P26+'Peralatan Mesin'!P28+'Peralatan Mesin'!P29+'Peralatan Mesin'!P38+'Peralatan Mesin'!P39+'Peralatan Mesin'!P40+'Peralatan Mesin'!P41+'Peralatan Mesin'!P42+'Peralatan Mesin'!P43+'Peralatan Mesin'!P44+'Peralatan Mesin'!P46+'Peralatan Mesin'!P48+'Peralatan Mesin'!P50+'Peralatan Mesin'!P51+'Peralatan Mesin'!P52+'Peralatan Mesin'!P56+'Peralatan Mesin'!P57+'Peralatan Mesin'!P104 -> 82295000
B21: Belanja Modal Peralatan Dapur | C21: Alat Kantor dan Rumah Tangga
B22: Belanja Modal Peralatan Alat Ukur | C22: Alat Bengkel dan Alat Ukur
B23: Belanja Modal Peralatan Rambu-rambu/Patok Tanah | C23: Peralatan dan Mesin Lainnya
B24: Belanja Modal Peralatan Khusus Kesehatan | C24: Alat Kesehatan | D24: ='Peralatan Mesin'!P77+'Peralatan Mesin'!P86 -> 5350000
B25: Belanja Modal Peralatan Khusus Pertanian/Peternakan/Oerikanan | C25: Alat Pertanian dan Perikanan
B26: Belanja Modal Mesin | C26: Peralatan dan Mesin Lainnya | D26: ='Peralatan Mesin'!P49 -> 7000000
B27: Belanja Modal Pengadaan Alat-alat Besar | C27: Alat Besar
B28: Belanja Modal Alat Angkutan | C28: Alat Angkutan
B29: Belanja Modal Alat Kantor dan Rumah Tangga | C29: Alat Kantor dan Rumah Tangga
B30: Belanja Modal Alat Pengeboran | C30: Alat Pengeboran
B31: Belanja Modal Peralatan Olah Raga | C31: Peralatan Olah Raga
B32: Belanja Modal Alat Produksi Pengolahan dan Pemurnian | C32: Alat Produksi, Pengolahan dan Pemurnian
B33: Belanja Modal Honor Tim Pengadaan (Kendaraan) | C33: Alat Angkutan
B34: Belanja Modal Kendaraan Darat Bermotor | C34: Alat Angkutan | D34: ='Peralatan Mesin'!P25+'Peralatan Mesin'!P80+'Peralatan Mesin'!P98 -> 324500000
B35: Belanja Modal Kendaraan Darat Tidak Bermotor | C35: Alat Angkutan
B36: Belanja Modal Kendaraan Air Bermotor | C36: Alat Angkutan
B37: Belanja Modal Kendaraan Air Tidak Bermotor | C37: Alat Angkutan
B38: ASET GEDUNG DAN BANGUNAN | D38: =SUM(D39:D63) -> 853414000
B39: Belanja Modal Gedung, Bangunan, Taman | C39: Bangunan Gedung Kantor | D39: ='Gedung Bangunan'!P12+'Gedung Bangunan'!P14+'Gedung Bangunan'!P17+'Gedung Bangunan'!P30+'Gedung Bangunan'!P42+'Gedung Bangunan'!P43 -> 507184000
C40: Bangunan Gudang
C41: Bangunan Gedung Bengkel
...
