Workbook

Sheet Silpa
A1: SISA LEBIH PEMBIAYAAN ANGGARAN
A3: Saldo Awal Kas (Saldo Akhir 2024) | C3: 114396779
A4: Penerimaan 2025 | B4: =2137969811 -> 2137969811
A5: Pengeluaran 2025 | B5: 1902090327
A6: Kenaikan/Penurunan Kas | C6: =B4-B5 -> 235879484
A7: Penerimaan Pembiayaan (diluar Silpa) | B7: 0
A8: Pengeluaran Pembiayaan | B8: 0
C9: =B7-B8 -> 0
A10: Saldo Akhir Kas 2025 | C10: =C3+C6+C9 -> 350276263
A11: Terdiri atas :
A12: - Kas di Bendahara Desa | B12: 0
A13: - Rekening Kas Desa | B13: 350276263 | C13: =B12+B13 -> 350276263
A15: Rincian Saldo Akhir Kas 2025 per Sumber Dana :
A16: - Pendapatan Asli Desa | B16: 2717
A17: - Alokasi Dana Desa | B17: 98748346
A18: - Dana Desa | B18: 227637500
A19: - Penerimaan Bagi Hasil Pajak Retribusi Daerah | B19: 17522083
A20: - Penerimaan Bantuan Keuangan Kab/Kota | B20: 5005000
A21: - Penerimaan Bantuan Keuangan Provinsi | B21: 210000
A22: - Pendapatan Lain-lain | B22: 1150617
B23: =SUM(B16:B22) -> 350276263 | C23: =C10-B23 -> 0
B26: Desa Klego, 31 Desember 2025
B27: Kepala Desa Klego
B31: GUNTUR HERU SUPRAPTO
A32: CATATAN :
A33: Silpa termasuk bunga bank dan biaya administrasi bank bulan Desember

Sheet Piutang
A2: PEMERINTAH DESA KLEGO
A3: DAFTAR PIUTANG
A4: PER 31 DESEMBER 2025
A6: NO. | B6: URAIAN | C6: Tahun Pengakuan Piutang Sesuai Perjanjian Sewa | D6: SALDO PIUTANG
D7: 31 Des 2024 | E7: PENAMBAHAN (Piutang 2025) | F7: PENGURANGAN (Piutang 2025) | G7: 31 Des 2025
D8: 1 | E8: 2 | F8: 3 | G8: 4=1+2-3
A10: 1 | B10: Piutang Sewa Tanah | C10: 2022 | D10: 22480000 | E10: 0 | F10: 480000 | G10: =D10+E10-F10 -> 22000000
A11: 2 | B11: Piutang Sewa Tanah | C11: 2023 | D11: 27455000 | E11: 0 | F11: 5455000 | G11: =D11+E11-F11 -> 22000000
A12: 3 | B12: Piutang Sewa Tanah | C12: 2024 | D12: 14425000 | E12: 0 | F12: 5825000 | G12: =D12+E12-F12 -> 8600000
A13: 4 | B13: Piutang Sewa Tanah | C13: 2025 | D13: 0 | E13: 25350000 | F13: 0 | G13: =D13+E13-F13 -> 25350000
A14: 5 | B14: Piutang Sewa Gedung | C14: 0 | D14: 0 | E14: 0 | F14: 0 | G14: =D14+E14-F14 -> 0
A15: 6 | B15: Piutang Sewa Peralatan | C15: 0 | D15: 0 | E15: 0 | F15: 0 | G15: =D15+E15-F15 -> 0
A16: 7 | B16: Piutang Bagi Hasil Pajak | C16: 0 | D16: 0 | E16: 0 | F16: 0 | G16: =D16+E16-F16 -> 0
A17: 8 | B17: Piutang Bagi Hasil Retribusi | C17: 0 | D17: 0 | E17: 0 | F17: 0 | G17: =D17+E17-F17 -> 0
A18: 9 | B18: Piutang Alokasi Dana Desa | C18: 0 | D18: 0 | E18: 0 | F18: 0 | G18: =D18+E18-F18 -> 0 | J18: Tahap I | K18: Tahap II | L18: Realisasi | M18: Pagu | N18: Selisih
A19: 10 | B19: Piutang Panjar Kegiatan | C19: 0 | D19: 0 | E19: 0 | F19: 0 | G19: =D19+E19-F19 -> 0 | I19: Bagi Hasil Pajak 2021 | J19: 29394000 | K19: 10623000 | L19: =SUM(J19:K19) -> 40017000 | M19: 40701149 | N19: =M19-L19 -> 684149
A20: 11 | B20: Piutang Lain-lain | C20: 0 | D20: 0 | E20: 0 | F20: 0 | G20: =D20+E20-F20 -> 0 | I20: Retribusi 2021 | J20: 3175000 | K20: 1568000 | L20: =SUM(J20:K20) -> 4743000 | M20: 5321328 | N20: =M20-L20 -> 578328
G21: =D21+E21-F21 -> 0 | I21: Jumlah | J21: =SUM(J19:J20) -> 32569000 | K21: =SUM(K19:K20) -> 12191000 | L21: =SUM(J21:K21) -> 44760000 | M21: =SUM(M19:M20) -> 46022477 | N21: =SUM(N19:N20) -> 1262477
D22: =SUM(D9:D21) -> 64360000 | E22: =SUM(E9:E21) -> 25350000 | F22: =SUM(F9:F21) -> 11760000 | G22: =SUM(G10:G21) -> 77950000 | O22: =G22-D22 -> 13590000
F24: =Silpa!B26 -> Desa Klego, 31 Desember 2025
F25: Kepala Desa Klego
F29: GUNTUR HERU SUPRAPTO
A30: CATATAN :
B31: 1) Saldo Piutang 31 Desember 2019 disisi sesuai dengan piutang yang tersaji dalam LKMD 2019
B32: 2) Penambahan disini merupakan pembentukan piutang baru di tahun 2020
B33: 3) Pengurangan disini merupakan pelunasan piutang 2019 yang terbayarkan selama tahun 2020

Sheet Persediaan
A2: PEMERINTAH DESA KLEGO
A3: PERSEDIAAN AKHIR
A4: PER 31 DESEMBER 2025
A6: Kode Desa | B6: Nama Desa | C6: PERSEDIAAN | L6: Jumlah
C7: Nama Barang | D7: Materai | E7: Alat Tulis Kantor | F7: Blangko dan Barang Cetakan | G7: Alat Listrik | H7: Persediaan Bahan/Material | I7: Bahan / Peralatan Kebersihan | J7: Persediaan Lain-Lain | K7: Makan minum
L8: =SUM(D8:K8) -> 0
A9: 2009 | B9: Klego | C9: Materai 10.000 | D9: =6*10000 -> 60000 | F9: 0 | G9: 0 | H9: 0 | I9: 0 | J9: 0 | L9: =SUM(D9:K9) -> 60000
C10: Kertas HVS A4 70 gram | E10: 390000 | L10: =SUM(D10:K10) -> 390000
C11: Kertas HVS F4 70 gram | E11: 140000 | L11: =SUM(D11:K11) -> 140000
C12: Tinta Printer Epson (Black) | E12: 250000 | L12: =SUM(D12:K12) -> 250000
C13: Tinta Printer Epson (Cyan) | E13: 125000 | L13: =SUM(D13:K13) -> 125000
L14: =SUM(D14:K14) -> 0
L15: =SUM(D15:K15) -> 0
L16: =SUM(D16:K16) -> 0
L17: =SUM(D17:K17) -> 0
A18: JUMLAH | D18: =SUM(D8:D16) -> 60000 | E18: =SUM(E8:E16) -> 905000 | F18: =SUM(F8:F16) -> 0 | G18: =SUM(G8:G16) -> 0 | H18: =SUM(H8:H16) -> 0 | I18: =SUM(I8:I16) -> 0 | J18: =SUM(J8:J16) -> 0 | K18: =SUM(K8:K16) -> 0 | L18: =SUM(L8:L16) -> 965000
J20: =Piutang!F24 -> Desa Klego, 31 Desember 2025
J21: Kepala Desa Klego
J25: GUNTUR HERU SUPRAPTO

Sheet Investasi
A2: PEMERINTAH DESA KLEGO
A3: DAFTAR INVESTASI
A4: PER 31 DESEMBER 2025
A6: No. | B6: Unit Pengelola / Nama Program | C6: Tahun Pengakuan | D6: Saldo Awal (sesuai Investasi s/d 2025) | E6: Penambahan 2025 | F6: Pengurangan 2025 | G6: Saldo Akhir
A7: 1 | B7: 2 | D7: 3 | E7: 4 | F7: 5 | G7: 6 = 3 + 4 -5
A9: 1 | B9: Penyertaan Modal BUMADesa 2019 | C9: 2019 | D9: 200000000 | G9: =D9+E9-F9 -> 200000000
A10: 2 | B10: Penyertaan Modal BUMDesa 2020 | C10: 2020 | D10: 50000000 | E10: 0 | F10: 0 | G10: =D10+E10-F10 -> 50000000
A12: Jumlah | D12: =SUM(D8:D11) -> 250000000 | E12: =SUM(E8:E11) -> 0 | F12: =SUM(F8:F11) -> 0 | G12: =D12+E12-F12 -> 250000000
E13: NIP. 197107271998031005
F15: =Persediaan!J20 -> Desa Klego, 31 Desember 2025
F16: Kepala Desa Klego
F20: GUNTUR HERU SUPRAPTO

Sheet Dana Cadangan
A2: PEMERINTAH DESA KLEGO
A3: DAFTAR DANA CADANGAN
A4: PER 31 DESEMBER 2025
A6: No. | B6: Unit Pengelola / Nama Program | C6: Saldo Awal | D6: Pembiayaan | F6: Saldo Akhir
D7: Penerimaan (yg di belanjakan sesuai program kegiatan) | E7: Pengeluaran
A8: 1 | B8: 2 | C8: 3 | D8: 4 | E8: 5 | F8: 6= 3-4+5
A10: 1 | B10: Dana Cadangan | C10: 0 | D10: 0 | E10: 0 | F10: =C10-D10+E10 -> 0
F11: =C11-D11+E11 -> 0
F12: =C12-D12+E12 -> 0
A14: Jumlah | C14: =SUM(C10:C13) -> 0 | D14: =SUM(D10:D13) -> 0 | E14: =SUM(E10:E13) -> 0 | F14: =C14-D14+E14 -> 0
E17: =Investasi!F15 -> Desa Klego, 31 Desember 2025
E18: Kepala Desa Klego
E22: GUNTUR HERU SUPRAPTO

Sheet Pajak
A2: PEMERINTAH DESA KLEGO
A3: DAFTAR HUTANG PAJAK
A4: PER 31 DESEMBER 2025
A6: No. | B6: Uraian | C6: Hutang Pajak 2024 | D6: Hutang Pajak | F6: Saldo Akhir
D7: Pengurangan Hutang Pajak (Pembayaran Hutang) | E7: Pembentukan Hutang Pajak 2025
A8: 1 | B8: 2 | C8: 3 | D8: 4 | E8: 5 | F8: 6= 3-4+5
A9: 1 | B9: Pajak PPN Pusat | C9: 0 | D9: 0 | E9: 0 | F9: =C9-D9+E9 -> 0
A10: 2 | B10: Pajak PPh Pasal 21 | C10: 0 | D10: 0 | E10: 0 | F10: =C10-D10+E10 -> 0
A11: 3 | B11: Pajak PPh Pasal 22 | C11: 0 | D11: 0 | E11: 0 | F11: =C11-D11+E11 -> 0
A12: 4 | B12: Pajak PPh Pasal 23 | C12: 0 | D12: 0 | E12: 0 | F12: =C12-D12+E12 -> 0
A13: 5 | B13: Pajak PPh Lainnya | C13: 0 | D13: 0 | E13: 0 | F13: =C13-D13+E13 -> 0
A14: Jumlah | C14: =SUM(C9:C13) -> 0 | D14: =SUM(D9:D13) -> 0 | E14: =SUM(E9:E13) -> 0 | F14: =C14-D14+E14 -> 0
E17: =Aset!F94 -> Desa Klego, 31 Desember 2025
E18: Kepala Desa Klego
E22: GUNTUR HERU SUPRAPTO
A24: CATATAN :
B25: 1) Kolom 4 harap di kasih keterangan tanggal berapa pembayaran hutang pajaknya

Sheet Aset
B1: PEMERINTAH DESA KLEGO
B2: PENAMBAH DAN PENGURANG ASET TETAP
B3: PER 31 DESEMBER 2025
B5: NO | C5: URAIAN | D5: SALDO AWAL 2025 (LKMD 2025) | E5: Tahun 2025 | G5: SALDO AKHIR 2025
E6: Penambahan | F6: Pengurangan
B7: 1 | C7: 2 | D7: 3 | E7: 4 | F7: 5 | G7: 6=3+4-5
B8: 1 | C8: Tanah | D8: =SUM(D9:D22) -> 28670245600 | E8: =SUM(E9:E22) -> 0 | F8: =SUM(F9:F22) -> 0 | G8: =SUM(G9:G22) -> 28670245600
C9: Tanah Kas Desa | D9: 0 | E9: 0 | F9: 0 | G9: =D9+E9-F9 -> 0
C10: Tanah Perkampungan | D10: 7703802600 | E10: 0 | F10: 0 | G10: =D10+E10-F10 -> 7703802600
C11: Tanah Pertanian | D11: 17576048000 | E11: 0 | F11: 0 | G11: =D11+E11-F11 -> 17576048000
C12: Tanah Perkebunan | D12: 0 | E12: 0 | F12: 0 | G12: =D12+E12-F12 -> 0
C13: Tanah Hutan | D13: 0 | E13: 0 | F13: 0 | G13: =D13+E13-F13 -> 0
C14: Tanah Kebun Campuran | D14: 0 | E14: 0 | F14: 0 | G14: =D14+E14-F14 -> 0
C15: Tanah Kolam Ikan | D15: 0 | E15: 0 | F15: 0 | G15: =D15+E15-F15 -> 0
C16: Tanah Danau/Rawa | D16: 0 | E16: 0 | F16: 0 | G16: =D16+E16-F16 -> 0
C17: Tanah Tandus/Rusak | D17: 0 | E17: 0 | F17: 0 | G17: =D17+E17-F17 -> 0
C18: Tanah Alang-alang dan Padang Rumput | D18: 0 | E18: 0 | F18: 0 | G18: =D18+E18-F18 -> 0
C19: Tanah Pertambangan | D19: 0 | E19: 0 | F19: 0 | G19: =D19+E19-F19 -> 0
C20: Tanah untuk Banguna Gedung | D20: 1556171000 | E20: 0 | F20: 0 | G20: =D20+E20-F20 -> 1556171000
... C22: Tanah Penggunaan Lainnya | D22: 1834224000 | E22: 0 | F22: 0 | G22: =D22+E22-F22 -> 1834224000
B23: 2 | C23: Peralatan dan Mesin | D23: =SUM(D24:D35) -> 589065000 | E23: =SUM(E24:E35) -> 38150000 | F23: =SUM(F25:F35) -> 0 | G23: =SUM(G24:G35) -> 627215000
C24: Alat Studio, Komunikasi dan Pemencar | D24: 35090000 | E24: 0 | F24: 0 | G24: =D24+E24-F24 -> 35090000
C25: Komputer | D25: =119830000+15000000 -> 134830000 | E25: 38150000 | F25: 0 | G25: =D25+E25-F25 -> 172980000
C26: Alat Kantor dan Rumah Tangga | D26: =78805000+3490000 -> 82295000 | E26: 0 | F26: 0 | G26: =D26+E26-F26 -> 82295000
C27: Alat Bengkel dan Alat Ukur | D27: 0 | E27: 0 | F27: 0 | G27: =D27+E27-F27 -> 0
C28: Alat Kesehatan | D28: 5350000 | E28: 0 | F28: 0 | G28: =D28+E28-F28 -> 5350000
C29: Alat Pertanian dan Perikanan | D29: 0 | E29: 0 | F29: 0 | G29: =D29+E29-F29 -> 0
C30: Peralatan dan Mesin Lainnya | D30: 7000000 | E30: 0 | F30: 0 | G30: =D30+E30-F30 -> 7000000
C31: Alat Besar | D31: 0 | E31: 0 | F31: 0 | G31: =D31+E31-F31 -> 0
C32: Alat Angkutan | D32: =40500000+284000000 -> 324500000 | E32: 0 | F32: 0 | G32: =D32+E32-F32 -> 324500000
C33: Alat Pengeboran | D33: 0 | E33: 0 | F33: 0 | G33: =D33+E33-F33 -> 0
C34: Peralatan Olah Raga | D34: 0 | E34: 0 | F34: 0 | G34: =D34+E34-F34 -> 0
C35: Alat Produksi, Pengolahan dan Pemurnian | D35: 0 | E35: 0 | F35: 0 | G35: =D35+E35-F35 -> 0
B36: 3 | C36: Gedung dan Bangunan | D36: =SUM(D37:D61) -> 838776500 | E36: =SUM(E37:E61) -> 14637500 | F36: =SUM(F37:F61) -> 0 | G36: =SUM(G37:G61) -> 853414000
C37: Bangunan Gedung Kantor | D37: 507184000 | E37: 0 | F37: 0 | G37: =D37+E37-F37 -> 507184000
C38: Bangunan Gudang | D38: 0 | E38: 0 | F38: 0 | G38: =D38+E38-F38 -> 0
C39: Bangunan Gedung Bengkel | D39: 0 | E39: 0 | F39: 0 | G39: =D39+E39-F39 -> 0
C40: Bangunan Gedung Instalasi | D40: 0 | E40: 0 | F40: 0 | G40: =D40+E40-F40 -> 0
C41: Bangunan Gedung Laboratorium, | D41: 0 | E41: 0 | F41: 0 | G41: =D41+E41-F41 -> 0
C42: Bangunan Kesehatan | D42: 15000000 | E42: 0 | F42: 0 | G42: =D42+E42-F42 -> 15000000
...

Sheet KK
B1: KERTAS KERJA LAPORAN KEKAYAAN MILIH DESA
B3: URAIAN | D3: 2024 | E3: 2025
B4: ASET LANCAR | D4: =SUM(D5:D22) -> 179511779 | E4: =SUM(E5:E22) -> 429191263 | G4: =E4-G7-G17 -> 415391263
C5: Kas di Bendahara Desa | D5: 0 | E5: =Silpa!B12 -> 0
C6: Rekening Kas Desa | D6: =Silpa!C3 -> 114396779 | E6: =Silpa!B23 -> 350276263 | G6: =E6-114354527 -> 235921736
C7: Piutang Sewa Tanah | D7: =Piutang!D10+Piutang!D11+Piutang!D12 -> 64360000 | E7: =Piutang!G22 -> 77950000 | G7: =E7-D7 -> 13590000
C8: Piutang Sewa Gedung | D8: =Piutang!D14 -> 0 | E8: =Piutang!G14 -> 0
C9: Piutang Sewa Peralatan | D9: =Piutang!D15 -> 0 | E9: =Piutang!G15 -> 0
C10: Piutang Bagi Hasil Pajak | D10: =Piutang!D16 -> 0 | E10: =Piutang!G16 -> 0 | G10: =D10+D11 -> 0
C11: Piutang Bagi Hasil Retribusi | D11: =Piutang!D17 -> 0 | E11: =Piutang!G17 -> 0
C12: Piutang Alokasi Dana Desa | D12: =Piutang!D18 -> 0 | E12: =Piutang!G18 -> 0
C13: Piutang Panjar Kegiatan | D13: =Piutang!D19 -> 0 | E13: =Piutang!G19 -> 0
C14: Piutang Lain-lain | D14: =Piutang!D20 -> 0 | E14: =Piutang!G20 -> 0
C15: Persediaan Benda Pos dan Materai | D15: 100000 | E15: =Persediaan!D18 -> 60000 | G15: =SUM(E15:E16) -> 965000
C16: Persediaan Alat Tulis Kantor | D16: 655000 | E16: =Persediaan!E18 -> 905000 | G16: =SUM(D15:D16) -> 755000
C17: Persediaan Blangko dan Barang Cetakan | D17: =Piutang!D23 -> 0 | E17: =Persediaan!F18 -> 0 | G17: =G15-G16 -> 210000
C18: Persediaan Alat-Alat Listrik/Lampu/Batterai | D18: =Piutang!D24 -> 0 | E18: =Persediaan!G18 -> 0
C19: Persediaan Bahan/Material | D19: =Piutang!D25 -> 0 | E19: =Persediaan!H18 -> 0
C20: Persediaan Alat-alat Kebersihan/Bahan Pembersih | D20: =Piutang!D26 -> 0 | E20: =Persediaan!I18 -> 0
C21: Persediaan Bibit Hewan/Tanaman | D21: =Piutang!D27 -> 0 | E21: =Persediaan!J18 -> 0
C22: Persediaan Makan Minum | D22: 0 | E22: =Persediaan!K18 -> 0
C23: Persediaan Barang Untuk Dihibahkan kepada Masyarakat | D23: 0 | E23: 0
B24: INVESTASI | D24: =+D25 -> 250000000 | E24: =+E25 -> 250000000
C25: Penyertaan Modal Pemerintah Desa | D25: =Investasi!D12 -> 250000000 | E25: =Investasi!G12 -> 250000000
B26: ASET TETAP | D26: =SUM(D27:D102) -> 36238354950 | E26: =SUM(E27:E102) -> 37240430950
C27: Tanah Kas Desa | D27: =Aset!D9 -> 0 | E27: =Aset!G9 -> 0
C28: Tanah Perkampungan | D28: =Aset!D10 -> 7703802600 | E28: =Aset!G10 -> 7703802600
C29: Tanah Pertanian | D29: =Aset!D11 -> 17576048000 | E29: =Aset!G11 -> 17576048000
C30: Tanah Perkebunan | D30: =Aset!D12 -> 0 | E30: =Aset!G12 -> 0
C31: Tanah Hutan | D31: =Aset!D13 -> 0 | E31: =Aset!G13 -> 0
C32: Tanah Kebun Campuran | D32: =Aset!D14 -> 0 | E32: =Aset!G14 -> 0
C33: Tanah Kolam Ikan | D33: =Aset!D15 -> 0 | E33: =Aset!G15 -> 0
C34: Tanah Danau/Rawa | D34: =Aset!D16 -> 0 | E34: =Aset!G16 -> 0
C35: Tanah Tandus/Rusak | D35: =Aset!D17 -> 0 | E35: =Aset!G17 -> 0
C36: Tanah Alang-alang dan Padang Rumput | D36: =Aset!D18 -> 0 | E36: =Aset!G18 -> 0
C37: Tanah Pertambangan | D37: =Aset!D19 -> 0 | E37: =Aset!G19 -> 0
C38: Tanah untuk Banguna Gedung | D38: =Aset!D20 -> 1556171000 | E38: =Aset!G20 -> 1556171000
... C40: Tanah Penggunaan Lainnya | D40: =Aset!D22 -> 1834224000 | E40: =Aset!G22 -> 1834224000
C41: Alat Studio, Komunikasi dan Pemencar | D41: =Aset!D24 -> 35090000 | E41: =Aset!G24 -> 35090000
C42: Komputer | D42: =Aset!D25 -> 134830000 | E42: =Aset!G25 -> 172980000 | G42: =E42-D42 -> 38150000
...
